<sdf version='1.11'>
  <model name='mini1'>
    <link name='base_link'>
      <inertial>
        <pose>1.9762e-15 2.3176e-15 0.014059 3.1415926535000001 0 0</pose>
        <mass>0.061943100000000001</mass>
        <inertia>
          <ixx>2.9645000000000002e-05</ixx>
          <ixy>0</ixy>
          <ixz>0</ixz>
          <iyy>2.9645000000000002e-05</iyy>
          <iyz>0</iyz>
          <izz>5.7154999999999997e-05</izz>
        </inertia>
      </inertial>
      <collision name='base_link_collision'>
        <pose>0 0 0 3.1415926535000001 0 0</pose>
        <geometry>
          <mesh>
            <scale>1 1 1</scale>
            <uri>../meshes/base_link.STL</uri>
          </mesh>
        </geometry>
        <surface>
          <contact>
            <collide_bitmask>0</collide_bitmask>
          </contact>
        </surface>
      </collision>
      <visual name='base_link_visual'>
        <pose>0 0 0 3.1415926535000001 0 0</pose>
        <geometry>
          <mesh>
            <scale>1 1 1</scale>
            <uri>../meshes/base_link.STL</uri>
          </mesh>
        </geometry>
        <material>
          <diffuse>1 1 1 1</diffuse>
          <ambient>1 1 1 1</ambient>
        </material>
      </visual>
      <!-- Approximate collision for stable contacts -->
      <collision name='base_link_collision_approx'>
        <pose>0 0 0 0 0 0</pose>
        <geometry>
          <box>
            <size>0.12 0.12 0.03</size>
          </box>
        </geometry>
      </collision>
    </link>
    <joint name='joint1' type='revolute'>
      <pose relative_to='base_link'>0 0 0 3.1415926535000001 0 0</pose>
      <parent>base_link</parent>
      <child>link1</child>
      <axis>
        <xyz>0 0 -1</xyz>
        <limit>
          <lower>-3.1415926535000001</lower>
          <upper>3.1415926535000001</upper>
          <effort>9</effort>
          <velocity>18</velocity>
        </limit>
        <dynamics>
          <spring_reference>0</spring_reference>
          <spring_stiffness>0</spring_stiffness>
        </dynamics>
      </axis>
    </joint>
    <link name='link1'>
      <pose relative_to='joint1'>0 0 0 0 0 0</pose>
      <inertial>
        <pose>0.0095259999999999997 -0.018612 -0.059459999999999999 0 0 0</pose>
        <mass>1.281922</mass>
        <inertia>
          <ixx>0.0029041000000000002</ixx>
          <ixy>-4.8900000000000003e-05</ixy>
          <ixz>0.0004728</ixz>
          <iyy>0.0026898</iyy>
          <iyz>2.4199999999999999e-05</iyz>
          <izz>0.0010640000000000001</izz>
        </inertia>
      </inertial>
      <collision name='link1_collision'>
        <pose>0 0 0 0 0 0</pose>
        <geometry>
          <mesh>
            <scale>1 1 1</scale>
            <uri>../meshes/link1.STL</uri>
          </mesh>
        </geometry>
        <surface>
          <contact>
            <collide_bitmask>0</collide_bitmask>
          </contact>
        </surface>
      </collision>
      <visual name='link1_visual'>
        <pose>0 0 0 0 0 0</pose>
        <geometry>
          <mesh>
            <scale>1 1 1</scale>
            <uri>../meshes/link1.STL</uri>
          </mesh>
        </geometry>
        <material>
          <diffuse>0.941174984 0.941174984 0.941174984 1</diffuse>
          <ambient>0.941174984 0.941174984 0.941174984 1</ambient>
        </material>
      </visual>
      <!-- Approximate collision for stable contacts -->
      <collision name='link1_collision_approx'>
        <pose>0 0 0 0 0 0</pose>
        <geometry>
          <box>
            <size>0.16 0.05 0.05</size>
          </box>
        </geometry>
      </collision>
    </link>
    <joint name='joint2' type='revolute'>
      <pose relative_to='link1'>0.041549999999999997 0 -0.09955 3.1415926535897931 1.5707926536359933 3.1415926535897931</pose>
      <parent>link1</parent>
      <child>link2</child>
      <axis>
        <xyz>0 0 -1</xyz>
        <limit>
          <lower>-1.1570796000000001</lower>
          <upper>1.1570796000000001</upper>
          <effort>9</effort>
          <velocity>18</velocity>
        </limit>
        <dynamics>
          <spring_reference>0</spring_reference>
          <spring_stiffness>0</spring_stiffness>
        </dynamics>
      </axis>
    </joint>
    <link name='link2'>
      <pose relative_to='joint2'>0 0 0 0 0 0</pose>
      <inertial>
        <pose>0.095881999999999995 -2.8714e-05 0.022099000000000001 0 0 0</pose>
        <mass>0.64904139999999999</mass>
        <inertia>
          <ixx>0.0001875</ixx>
          <ixy>9.9999999999999995e-07</ixy>
          <ixz>-0.000202</ixz>
          <iyy>0.001536</iyy>
          <iyz>5.9999999999999997e-07</iyz>
          <izz>0.0015361999999999999</izz>
        </inertia>
      </inertial>
      <collision name='link2_collision'>
        <pose>0 0 0 0 0 0</pose>
        <geometry>
          <mesh>
            <scale>1 1 1</scale>
            <uri>../meshes/link2.STL</uri>
          </mesh>
        </geometry>
        <surface>
          <contact>
            <collide_bitmask>0</collide_bitmask>
          </contact>
        </surface>
      </collision>
      <visual name='link2_visual'>
        <pose>0 0 0 0 0 0</pose>
        <geometry>
          <mesh>
            <scale>1 1 1</scale>
            <uri>../meshes/link2.STL</uri>
          </mesh>
        </geometry>
        <material>
          <diffuse>0.941174984 0.941174984 0.941174984 1</diffuse>
          <ambient>0.941174984 0.941174984 0.941174984 1</ambient>
        </material>
      </visual>
      <!-- Approximate collision for stable contacts -->
      <collision name='link2_collision_approx'>
        <pose>0 0 0 0 0 0</pose>
        <geometry>
          <box>
            <size>0.18 0.05 0.05</size>
          </box>
        </geometry>
      </collision>
    </link>
    <joint name='joint3' type='revolute'>
      <pose relative_to='link2'>0.14000000000000001 0 0.012449999999999999 -3.1415853071795872 0 0</pose>
      <parent>link2</parent>
      <child>link3</child>
      <axis>
        <xyz>0 0 -1</xyz>
        <limit>
          <lower>-0.78539800000000004</lower>
          <upper>1.1570796000000001</upper>
          <effort>9</effort>
          <velocity>18</velocity>
        </limit>
        <dynamics>
          <spring_reference>0</spring_reference>
          <spring_stiffness>0</spring_stiffness>
        </dynamics>
      </axis>
    </joint>
    <link name='link3'>
      <pose relative_to='joint3'>0 0 0 0 0 0</pose>
      <inertial>
        <pose>0.017873 0.0064590999999999997 0.042102000000000001 0 0 0</pose>
        <mass>0.64188029999999996</mass>
        <inertia>
          <ixx>0.00056840000000000005</ixx>
          <ixy>0.0001154</ixy>
          <ixz>5.3499999999999999e-05</ixz>
          <iyy>0.00057019999999999998</iyy>
          <iyz>-7.75e-05</iyz>
          <izz>0.00060019999999999995</izz>
        </inertia>
      </inertial>
      <collision name='link3_collision'>
        <pose>0 0 0 0 0 0</pose>
        <geometry>
          <mesh>
            <scale>1 1 1</scale>
            <uri>../meshes/link3.STL</uri>
          </mesh>
        </geometry>
        <surface>
          <contact>
            <collide_bitmask>0</collide_bitmask>
          </contact>
        </surface>
      </collision>
      <visual name='link3_visual'>
        <pose>0 0 0 0 0 0</pose>
        <geometry>
          <mesh>
            <scale>1 1 1</scale>
            <uri>../meshes/link3.STL</uri>
          </mesh>
        </geometry>
        <material>
          <diffuse>0.941174984 0.941174984 0.941174984 1</diffuse>
          <ambient>0.941174984 0.941174984 0.941174984 1</ambient>
        </material>
      </visual>
      <!-- Approximate collision for stable contacts -->
      <collision name='link3_collision_approx'>
        <pose>0 0 0 0 0 0</pose>
        <geometry>
          <box>
            <size>0.18 0.05 0.05</size>
          </box>
        </geometry>
      </collision>
    </link>
    <joint name='joint4' type='revolute'>
      <pose relative_to='link3'>0 0.012 0.053999999999999999 1.5708 0 0</pose>
      <parent>link3</parent>
      <child>link4</child>
      <axis>
        <xyz>0 0 -1</xyz>
        <limit>
          <lower>-3.1415926535000001</lower>
          <upper>3.1415926535000001</upper>
          <effort>3.5</effort>
          <velocity>18</velocity>
        </limit>
        <dynamics>
          <spring_reference>0</spring_reference>
          <spring_stiffness>0</spring_stiffness>
        </dynamics>
      </axis>
    </joint>
    <link name='link4'>
      <pose relative_to='joint4'>0 0 0 0 0 0</pose>
      <inertial>
        <pose>0.00010149000000000001 -0.00081877000000000002 0.13234000000000001 0 0 0</pose>
        <mass>0.49311369999999999</mass>
        <inertia>
          <ixx>0.0010794000000000001</ixx>
          <ixy>-5.9999999999999997e-07</ixy>
          <ixz>2.3e-06</ixz>
          <iyy>0.0010191</iyy>
          <iyz>-5.2899999999999998e-05</iyz>
          <izz>0.00024909999999999998</izz>
        </inertia>
      </inertial>
      <collision name='link4_collision'>
        <pose>0 0 0 0 0 0</pose>
        <geometry>
          <mesh>
            <scale>1 1 1</scale>
            <uri>../meshes/link4.STL</uri>
          </mesh>
        </geometry>
        <surface>
          <contact>
            <collide_bitmask>0</collide_bitmask>
          </contact>
        </surface>
      </collision>
      <visual name='link4_visual'>
        <pose>0 0 0 0 0 0</pose>
        <geometry>
          <mesh>
            <scale>1 1 1</scale>
            <uri>../meshes/link4.STL</uri>
          </mesh>
        </geometry>
        <material>
          <diffuse>0.941174984 0.941174984 0.941174984 1</diffuse>
          <ambient>0.941174984 0.941174984 0.941174984 1</ambient>
        </material>
      </visual>
      <!-- Approximate collision for stable contacts -->
      <collision name='link4_collision_approx'>
        <pose>0 0 0 0 0 0</pose>
        <geometry>
          <box>
            <size>0.18 0.04 0.04</size>
          </box>
        </geometry>
      </collision>
    </link>
    <joint name='joint5' type='revolute'>
      <pose relative_to='link4'>0 -0.0070000000000000001 0.16500000000000001 1.5708 0 0</pose>
      <parent>link4</parent>
      <child>link5</child>
      <axis>
        <xyz>0 0 -1</xyz>
        <limit>
          <lower>-2.3561939999999999</lower>
          <upper>2.3561939999999999</upper>
          <effort>3.5</effort>
          <velocity>18</velocity>
        </limit>
        <dynamics>
          <spring_reference>0</spring_reference>
          <spring_stiffness>0</spring_stiffness>
        </dynamics>
      </axis>
    </joint>
    <link name='link5'>
      <pose relative_to='joint5'>0 0 0 0 0 0</pose>
      <inertial>
        <pose>2.7229999999999998e-05 0.039361 0.0078019999999999999 0 0 0</pose>
        <mass>0.49783640000000001</mass>
        <inertia>
          <ixx>0.00048099999999999998</ixx>
          <ixy>9.9999999999999995e-08</ixy>
          <ixz>9.9999999999999995e-08</ixz>
          <iyy>0.0002856</iyy>
          <iyz>0.00013760000000000001</iyz>
          <izz>0.00038109999999999999</izz>
        </inertia>
      </inertial>
      <collision name='link5_collision'>
        <pose>0 0 0 0 0 0</pose>
        <geometry>
          <mesh>
            <scale>1 1 1</scale>
            <uri>../meshes/link5.STL</uri>
          </mesh>
        </geometry>
        <surface>
          <contact>
            <collide_bitmask>0</collide_bitmask>
          </contact>
        </surface>
      </collision>
      <visual name='link5_visual'>
        <pose>0 0 0 0 0 0</pose>
        <geometry>
          <mesh>
            <scale>1 1 1</scale>
            <uri>../meshes/link5.STL</uri>
          </mesh>
        </geometry>
        <material>
          <diffuse>0.941174984 0.941174984 0.941174984 1</diffuse>
          <ambient>0.941174984 0.941174984 0.941174984 1</ambient>
        </material>
      </visual>
      <!-- Approximate collision for stable contacts -->
      <collision name='link5_collision_approx'>
        <pose>0 0 0 0 0 0</pose>
        <geometry>
          <box>
            <size>0.10 0.04 0.04</size>
          </box>
        </geometry>
      </collision>
    </link>
    <joint name='joint6' type='revolute'>
      <pose relative_to='link5'>0 0.087499999999999994 -0.0070000000000000001 -1.5708 0 0</pose>
      <parent>link5</parent>
      <child>link6</child>
      <axis>
        <xyz>0 0 -1</xyz>
        <limit>
          <lower>-3.1415926535000001</lower>
          <upper>3.1415926535000001</upper>
          <effort>3.5</effort>
          <velocity>18</velocity>
        </limit>
        <dynamics>
          <spring_reference>0</spring_reference>
          <spring_stiffness>0</spring_stiffness>
        </dynamics>
      </axis>
    </joint>
    <link name='link6'>
      <pose relative_to='joint6'>0 0 0 0 0 0</pose>
      <inertial>
        <pose>-1.7208000000000001e-15 -6.9610999999999999e-16 0.011978000000000001 0 0 0</pose>
        <mass>1.02e-06</mass>
        <inertia>
          <ixx>1.3e-06</ixx>
          <ixy>0</ixy>
          <ixz>0</ixz>
          <iyy>1.1999999999999999e-06</iyy>
          <iyz>0</iyz>
          <izz>5.9999999999999997e-07</izz>
        </inertia>
      </inertial>
      <collision name='link6_collision'>
        <pose>0 0 0 0 0 0</pose>
        <geometry>
          <mesh>
            <scale>1 1 1</scale>
            <uri>../meshes/link6.STL</uri>
          </mesh>
        </geometry>
        <surface>
          <contact>
            <collide_bitmask>0</collide_bitmask>
          </contact>
        </surface>
      </collision>
      <visual name='link6_visual'>
        <pose>0 0 0 0 0 0</pose>
        <geometry>
          <mesh>
            <scale>1 1 1</scale>
            <uri>../meshes/link6.STL</uri>
          </mesh>
        </geometry>
        <material>
          <diffuse>1 1 1 1</diffuse>
          <ambient>1 1 1 1</ambient>
        </material>
      </visual>
      <!-- Approximate collision for stable contacts -->
      <collision name='link6_collision_approx'>
        <pose>0 0 0 0 0 0</pose>
        <geometry>
          <sphere>
            <radius>0.03</radius>
          </sphere>
        </geometry>
      </collision>
    </link>
  </model>
</sdf>
